Workbook

Sheet Cover
B2: AGENT TEST COVER
B3: Version: | C3: 1.0
B4: Updated date: | C4: 46277
B5: Project: | C5: AI IT Job Market Consultant
B7: Revision History:
B8: Effective date | C8: Version | D8: Module | E8: Description | F8: Publisher | G8: Reviewer | H8: Source of reference
B9: 46217 | C9: 0.1 | D9: agent-test-case-report.xlsx | E9: Agent test report template initiation | F9: V. T. Thanh | G9: V. T. Thanh
B10: 46217 | C10: 1.0 | D10: AIJMC, Gemini, ChatGPT | E10: Design and add AI agent test cases for the benchmark. | F10: V.T. Thanh | G10: V.T. Thanh

Sheet AIJMC Gemini Flash 
A1: AGENT TEST CASE
A3: Project: | B3: AI IT Job Market Consultant
A4: Module: | B4: AIJMC Gemini Flash
A5: Test environment: | B5: AIJMC Cloud Deployment
A6: Pass | B6: =COUNTIFS(K11:K199, "Pass", A11:A199, "<>*AI") -> 20 | D6: Judge Pass | E6: =COUNTIF(M12:M199,"Pass") -> 17 | F6: Pending | G6: =COUNTIFS(K11:K199, "Pending", A11:A199, "<>*AI") -> 3
A7: Fail | B7: =COUNTIFS(K11:K199, "Fail", A11:A199, "<>*AI") -> 7 | D7: Judge Fail | E7: =COUNTIF(M11:M199,"Fail") -> 9 | F7: Total test case | G7: =COUNTIF(A11:A199, "TC*") -> 30
A9: Test case ID | B9: Test level | C9: Test case name | D9: AI Agent Input | E9: Expected results | I9: Actual results | J9: Test date | K9: Status | L9: Judge result | M9: Judge Status | N9: Reference | O9: Test case purpose
A12: TC-01 | B12: Dễ | C12: Tìm tin tuyển dụng Python Developer | D12: Tôi muốn tìm các tin tuyển dụng Python Developer tại Việt Nam. | E12: Trả về danh sách tin tuyển dụng phù hợp với vị trí Python Developer tại Việt Nam và không đưa các vị trí không liên quan đến Python Developer vào danh sách chính. | I12: Dưới đây là danh sách các vị trí tuyển dụng Python Developer đang mở tuyển tại Việt Nam, cùng với phân tích tổng quan về mức lương và kỹ năng được yêu cầu nhiều nhất. 📋 Danh Sách Tin Tuyển Dụng Python Developer Nổi Bật Vị trí Công ty Cấp bậc Mô hình làm việc Kỹ năng chính Link ứng tuyển Senior Python Developer ISB Vietnam Company Senior Onsite AWS, API, PostgreSQL, Docker, Kubernetes, Milvus, Web3 Xem chi tiết Senior Python Developer Prestige Home Senior Onsite (Up to 40 triệu/tháng) Django, Redis, RESTful API Xem chi tiết Python Developer Accenture Mid Hybrid REST API, Software Engineering Xem chi tiết Lead Python Developer FPT Software Lead Onsite Flask, SOLID Principles, Team Leadership Xem chi tiết Senior Full-Stack Developer (Python/Node.js) ONE Tech Stop Vietnam Senior Onsite (Đà Nẵng) Python, Django, Cloud Architecture Xem chi tiết Lập Trình Viên Python VNPT Mid Onsite Python, Web Fundamentals Xem chi tiết 📊 Phân Tích Thị Trường & Kỹ Năng Yêu Cầu 1. Kỹ năng phổ biến được nhà tuyển dụng tìm kiếm Web Frameworks: Django, FastAPI, Flask. Database & Caching: PostgreSQL, MySQL, Redis, Elasticsearch. Cloud & DevOps: AWS, Docker, Kubernetes, CI/CD. Xu hướng mới: Các ứng dụng tích hợp AI/LLM, Vector Databases (Milvus), Web3, và Big Data/Data Engineering. 2. Mức lương tham khảo Mid-level Python Developer: Dao động từ $1,000 - $1,800 USD/tháng (~25 - 45 triệu VND). Senior / Lead Python Developer: Dao động từ $1,800 - $3,500+ USD/tháng (~45 - 85+ triệu VND), tùy thuộc vào chuyên môn về System Architecture, Cloud, hoặc AI. 💡 Lời Khuyên Dành Cho Ứng Viên Tập trung vào Framework & API: Nắm vững RESTful API, gRPC cùng với Django hoặc FastAPI để tối ưu hóa khả năng trúng tuyển vào các công ty sản xuất sản phẩm (Product) hoặc Outsourcing lớn. Kỹ năng Cloud & Microservices: Việc có kiến thức làm việc với Docker, Kubernetes và AWS/GCP là điểm cộng rất lớn đối với cấp bậc từ Mid-level trở lên. Cập nhật kiến thức AI/ML: Nhờ sự bùng nổ của GenAI, Python Developer có thêm lợi thế lớn nếu nắm rõ kiến thức làm việc với LLM, LangChain hoặc Vector Databases. Nếu bạn cần tư vấn sâu hơn về cách tối ưu CV cho vị trí Python Developer hoặc muốn tìm kiếm thêm thông tin ở địa điểm cụ thể (Hà Nội, TP.HCM, Đà Nẵng), hãy cho tôi biết! | J12: 46277 | K12: Pass | L12: { "judge_result": "PASS", "judge_status": "PASS", "reason": "The Actual Result successfully provides a list of relevant Python Developer job postings in Vietnam and does not include irrelevant positions, fulfilling the Expected Result and Test Case Purpose." } | M12: Pass | N12: No reference | O12: Kiểm tra khả năng truy xuất và cung cấp các tin tuyển dụng phù hợp với vị trí Python Developer tại Việt Nam.
A14: TC-02 | B14: Dễ | C14: Tìm việc Backend Developer | D14: Hãy tìm các tin tuyển dụng Backend Developer tại Việt Nam. | E14: Cung cấp các tin tuyển dụng thuộc nhóm Backend Developer và không tự tạo tên công ty hoặc tin tuyển dụng. | I14: Dưới đây là danh sách các tin tuyển dụng Backend Developer đang mở tuyển tại Việt Nam, cùng với phân tích tổng quan về thị trường, mức lương và các kỹ năng chuyên môn được yêu cầu phổ biến nhất. 📋 Danh Sách Tin Tuyển Dụng Backend Developer Nổi Bật Vị trí Công ty Cấp bậc Mô hình Mức lương Kỹ năng chính Link ứng tuyển Backend Developer Creative Force Mid Onsite 80,000,000 VND AWS, Microservices, .NET Core, AI, RESTful API Xem chi tiết Senior Backend Developer (Golang) VISION Advisory & Analytics Senior Onsite 1,500 - 3,500 USD Golang, Linux, PostgreSQL, Docker Xem chi tiết Back-End Developer (NodeJS) Công ty Cổ phần Smileviet Mid Onsite 800 - 1,200 USD NodeJS, MySQL, ReactJS Xem chi tiết Backend Developer (Python/.NET) LizAI Vietnam Junior / Senior Onsite 800 - 2,000 USD Python, .NET Core, SQL Xem chi tiết Backend Developer (Fintech) Pinetree Securities Mid Onsite Thương lượng Java Spring, AWS, Microservices, Kafka, Redis Xem chi tiết PHP Backend Developer LikeLion Vietnam Mid Onsite Thương lượng PHP, REST API, MySQL Xem chi tiết Back-End Developer GS25 Vietnam Mid Onsite Thương lượng Java, Python, OOP Xem chi tiết 📊 Phân Tích Thị Trường & Mức Lương Backend Developer 1. Mức lương trung bình (Benchmark) Junior / Fresher: $600 – $1,000 / tháng. Mid-level: $1,000 – $2,000 / tháng (hoặc khoảng 25 - 45 triệu VND). Các vị trí yêu cầu kiến trúc hệ thống chuyên sâu hoặc lĩnh vực Fintech/AI có thể đạt tới 80,000,000 VND. Senior / Lead: $2,000 – $3,500+ / tháng (tùy thuộc vào ngôn ngữ cốt lõi như Golang, Java Microservices, Cloud Architecture). 2. Các nhóm công nghệ (Tech Stack) phổ biến Ngôn ngữ lập trình được săn đón: Java (Spring Boot), Node.js (TypeScript/Express/NestJS), .NET Core, Python (Django/FastAPI) và Golang. Cơ sở dữ liệu: PostgreSQL, MySQL, MariaDB cùng với các giải pháp Caching/Message Queue như Redis, Apache Kafka, RabbitMQ. Hạ tầng & Cloud: Điện toán đám mây (AWS, GCP), Docker, Kubernetes, CI/CD, kiến trúc Microservices. 💡 Đánh Giá & Lời Khuyên Ứng Tuyển Đa dạng hóa Tech Stack: Ngoài ngôn ngữ chính (Java/Node.js/Python/.NET), việc sở hữu kỹ năng về Microservices, Docker/Kubernetes và Cloud (AWS/GCP) sẽ giúp bạn nâng cao đáng kể lợi thế cạnh tranh và mức thù lao. Ngành hàng ưu tiên: Các doanh nghiệp trong mảng Fintech, E-commerce, Tài chính - Chứng khoán và Đổi mới sáng tạo (AI/Web3) hiện đang chào đón các Backend Developer với mức đãi ngộ cao. Chuẩn bị hồ sơ: Nhấn mạnh các dự án thực tế có xử lý tải cao (High Throughput/Scalability), tối ưu hóa Database và thiết kế RESTful/GraphQL API. | J14: 46277 | K14: Pass | L14: { "judge_result": "PASS", "judge_status": "PASS", "reason": "The Actual Result successfully provides a list of real Backend Developer job postings in Vietnam and does not fabricate company names or job postings, completely satisfying the Expected Result and Test Case Purpose." } | M14: Pass | N14: No reference | O14: Kiểm tra khả năng tìm kiếm và trả về các tin tuyển dụng thuộc nhóm Backend Developer.
A16: TC-03 | B16: Dễ | C16: Tìm việc Frontend Developer | D16: Có những tin tuyển dụng Frontend Developer nào? | E16: Trả về các tin tuyển dụng liên quan đến Frontend Developer. Nếu có dữ liệu, cung cấp các trường như công ty, vị trí, địa điểm và đường dẫn hoặc nguồn tin. | I16: Dưới đây là danh sách các vị trí tuyển dụng Frontend Developer đang mở tuyển tại Việt Nam, kèm theo tổng quan về thị trường, mức lương và các kỹ năng chuyên môn được yêu cầu phổ biến. 📋 Danh Sách Tin Tuyển Dụng Frontend Developer Nổi Bật Vị trí Công ty Cấp bậc Mô hình Mức lương Kỹ năng chính Link ứng tuyển Frontend ReactJS Developer Công ty cổ phần hàng hải Vsico Mid Hybrid 700 - 900 USD CSS, TypeScript, JavaScript, HTML Xem chi tiết Front-End Developer IncepIT Mid Onsite 800 - 2,500 USD AWS, Linux, PHP, JavaScript, HTML/CSS Xem chi tiết Senior Frontend Web Developer VISION Advisory & Analytics Senior Onsite Thỏa thuận TypeScript, CSS3, NextJS, HTML5 Xem chi tiết Frontend Developer (Shopify/Wordpress) SOLIS LAB Mid Onsite 800 - 1,200 USD ReactJS, CSS, HTML, Shopify, WordPress Xem chi tiết Frontend Developer (ReactJS) Bất Động Sản Hapulico Mid Onsite Thỏa thuận ReactJS, JavaScript, Web Frontend Xem chi tiết Fullstack Engineer (Frontend Focus) Cazoodle Junior - Mid Remote Thỏa thuận React, UI/UX, Web App Xem chi tiết Senior Frontend Web Developer SHINHAN DS Senior Onsite Thỏa thuận JavaScript, HTML/CSS, API, NoSQL Xem chi tiết Product Frontend Intern GEEK UP Intern Onsite Thỏa thuận ReactJS, HTML5, GitHub Xem chi tiết 📊 Phân Tích Thị Trường Tuyển Dụng Frontend 1. Phổ Mức Lương (Salary Range) Junior / Intern: Thường dao động từ 8 - 15 triệu VND (~350 - 650 USD). Mid-level (2 - 4 năm kinh nghiệm): Phổ biến trong khoảng 800 - 1,500 USD/tháng (tùy thuộc vào khả năng tiếng Anh và tech stack). Senior / Lead (4+ năm kinh nghiệm): Phổ lương mở rộng từ 1,800 - 2,500+ USD/tháng, đặc biệt ở các công ty sản xuất phần mềm (Product) hoặc các dự án quốc tế. 2. Kỹ Năng Yêu Cầu Phổ Biến (Top Tech Stack) Frameworks/Libraries: ReactJS / NextJS là bộ đôi chiếm ưu thế vượt trội trong phần lớn tin tuyển dụng hiện nay. Ngoài ra, Vue.js và Angular cũng giữ thị phần nhất định. Ngôn ngữ & Tiền xử lý: TypeScript đã trở thành tiêu chuẩn gần như bắt buộc cho các vị trí Mid/Senior bên cạnh HTML5/CSS3 và JavaScript (ES6+). Kỹ năng mở rộng: Hiểu biết về RESTful APIs, Tối ưu hiệu năng (Performance Optimization), UI/UX Design System, State Management (Redux, Zustand) và kinh nghiệm làm việc với các hệ thống CI/CD hoặc CMS (Shopify/WordPress). 💡 Lời Khuyên Cho Ứng Viên Nâng cao kiến thức TypeScript & Next.js: Đa số các công ty trả mức lương khá trở lên đều ưu tiên ứng viên thành thạo TypeScript và các Renderer Framework như Next.js để tối ưu SEO và Server-Side Rendering (SSR). Chú trọng tối ưu trải nghiệm người dùng (UX/Performance): Nắm vững kiến thức về Core Web Vitals, Responsive Design và accessibility (a11y) sẽ giúp bạn ghi điểm lớn trong các buổi phỏng vấn vị trí Senior. Nếu bạn cần tư vấn chi tiết hơn về mức lương theo cấp bậc cụ thể hoặc lộ trình nâng cao kỹ năng Frontend, hãy cho tôi biết! | J16: 46277 | K16: Pass | L16: { "judge_result": "PASS", "judge_status": "PASS", "reason": "The Actual Result successfully provides a list of Frontend Developer job postings along with relevant details such as the position, company, and application link, fulfilling the requirements of the Expected Result." } | M16: Pass | N16: No reference | O16: Kiểm tra khả năng truy xuất các tin tuyển dụng liên quan đến vị trí Frontend Developer.
A18: TC-04 | B18: Dễ | C18: Tìm việc React Developer | D18: Tìm giúp tôi các công việc yêu cầu React tại Việt Nam. | E18: Trả về các tin tuyển dụng có yêu cầu hoặc đề cập đến React. | I18: Dưới đây là danh sách các cơ hội việc làm yêu cầu React (ReactJS / React Native) tại Việt Nam, cùng với phân tích tổng quan về mức lương, cấp bậc và bộ kỹ năng đi kèm được các nhà tuyển dụng tìm kiếm phổ biến. 📋 Danh Sách Tin Tuyển Dụng Yêu Cầu React Nổi Bật Vị trí Công ty Cấp bậc Mô hình Mức lương Kỹ năng liên quan Link ứng tuyển Senior React Frontend Engineer Clearstone Software Senior Onsite 2,800 - 3,800 USD TypeScript, REST API, Front-end Ứng tuyển Lead React Native Developer CÔNG TY TNHH BRIDGETEK VIỆT NAM Lead Onsite 70 - 90 Triệu VND React Native, Mobile Development Ứng tuyển Sr. Frontend Dev (ReactJS, JS/TS) CÔNG TY TNHH AI MED ENGINE Mid/Senior Onsite 1,000 - 2,500 USD JavaScript, TypeScript, HTML5/CSS3 Ứng tuyển Frontend ReactJS (ReactJS, JS) Công ty TNHH RENDA Mid Hybrid 700 - 1,200 USD JavaScript, Front-end, ERP Ứng tuyển Frontend ReactJS Developer Công ty Cổ phần Hàng hải Vsico Mid Hybrid 700 - 900 USD TypeScript, JavaScript, HTML/CSS Ứng tuyển [HN] Senior ReactJS Engineer NAB Innovation Centre Vietnam Senior Hybrid Thỏa thuận TypeScript, JavaScript, Redux Ứng tuyển Senior Front-End Engineer (React & Micro Frontend) EPAM Vietnam Senior Remote Thỏa thuận TypeScript, Redux, Micro Frontend Ứng tuyển Senior Front-End Engineer EPAM Senior Onsite Thỏa thuận ReactJS, React Query, MS Azure, REST API Ứng tuyển Full-Stack ReactJS / NodeJS Developer FPT Software HN Mid Onsite Thỏa thuận ReactJS, NodeJS, PostgreSQL, MongoDB Ứng tuyển 📊 Phân Tích Nhu Cầu Tuyển Dụng React Tại Việt Nam 1. Phân Phối Mức Lương theo Cấp Bậc Mid-level (2 - 4 năm kinh nghiệm): Phổ biến trong khoảng 700 – 1,200 USD/tháng (tương đương 18 - 30 triệu VND). Senior-level (4+ năm kinh nghiệm): Dao động từ 1,000 – 3,800 USD/tháng (tương đương 25 - 95 triệu VND) tùy thuộc vào quy mô công ty và mức độ yêu cầu về kiến trúc hệ thống. Lead / Management: Có thể đạt 70 – 90 triệu VND/tháng (hoặc trên 3,000 USD/tháng). 2. Các Kỹ Năng Bổ Trợ Được Đòi Hỏi Nhiều Nhất TypeScript & JavaScript ES6+: Gần như là tiêu chuẩn bắt buộc đi kèm với ReactJS trong các dự án hiện đại. State Management: Redux, Context API, React Query/TanStack Query. Backend Knowledge (Full-stack): Nhu cầu tuyển kết hợp ReactJS + NodeJS tăng cao cho các vị trí Full-stack Developer. Kiến trúc Hiện đại: Micro Frontends, CI/CD, Cloud Service (AWS, Azure) thường được đưa vào yêu cầu cho cấp bậc Senior trở lên. 3. Xu Hướng Mô Hình Làm Việc Mô hình Hybrid và Remote khá phổ biến ở các vị trí ReactJS, đặc biệt là các công ty tư vấn phần mềm quốc tế (EPAM, NAB, Renda) giúp ứng viên linh hoạt về không gian làm việc. Nếu bạn muốn tìm hiểu sâu hơn về mức lương trung bình của một vai trò cụ thể, so sánh React với Vue/Angular, hoặc chuẩn bị cho phỏng vấn React, hãy cho tôi biết nhé! | J18: 46277 | K18: Pass | L18: { "judge_result": "PASS", "judge_status": "PASS", "reason": "The Actual Result successfully provides a list of job postings that require or mention React (ReactJS/React Native) in Vietnam, fully satisfying the Expected Result and Test Case Purpose." } | M18: Pass | N18: No reference | O18: Kiểm tra khả năng nhận diện và truy xuất các tin tuyển dụng có yêu cầu hoặc đề cập đến React.
A20: TC-05 | B20: Dễ | C20: Tìm việc Java Developer | D20: Tôi cần tìm tin tuyển dụng Java Developer ở Việt Nam. | E20: Cung cấp danh sách tin tuyển dụng phù hợp với Java Developer. Không nhầm Java với JavaScript. | I20: Dưới đây là thông tin chi tiết về các vị trí tuyển dụng Java Developer đang mở tại Việt Nam, cùng với phân tích tổng quan về mức lương, các kỹ năng liên quan và xu hướng tuyển dụng cho vai trò này. 📋 Danh Sách Tin Tuyển Dụng Java Developer Nổi Bật Vị trí Công ty Cấp bậc Mô hình Mức lương Kỹ năng chính Ứng tuyển Mid/Sr Java Developer (English Required) Rakuten Fintech Vietnam Mid / Senior Onsite 1,500 - 3,200 USD Spring, Unit Test, English Chi tiết Senior Java Developer (Spring/OOP) Nakivo Senior Onsite 2,000 - 2,500 USD Spring Framework, OOP Chi tiết Mid/Sr Java Developer Rakuten Fintech Vietnam Mid / Senior Onsite Lên đến 3,200 USD Microservices, API, JUnit, JavaEE Chi tiết Java Developer DTN E-Commerce Software Mid Onsite 15 - 25 Triệu VND Java, SQL, Database Chi tiết Java Developers DXC Vietnam Mid Hybrid Thỏa thuận Spring Boot, English, Japanese Chi tiết Java Developer GPBank Mid Onsite Thỏa thuận AWS, CI/CD, Docker Chi tiết Java Developer (Middle) Shinhan Vietnam Finance Mid Onsite Thỏa thuận Java, AngularJS, Front-End Chi tiết Java Developer Ngân Hàng Woori Việt Nam Mid Onsite Thỏa thuận Java Backend, Banking System Chi tiết 📊 Phân Tích Thị Trường Tuyển Dụng Java Tại Việt Nam 1. Nhu cầu & Lĩnh vực hoạt động Tài chính - Ngân hàng (Fintech & Banking): Nhóm ngành này (Shinhan Finance, Woori Bank, GPBank, Rakuten Fintech...) chiếm tỷ lệ tuyển dụng Java lớn nhất do tính bảo mật, ổn định và khả năng xử lý giao dịch quy mô lớn của Java ecosystem. Outsourcing & Product MNCs: Các tập đoàn như DXC, Nakivo liên tục tuyển dụng lập trình viên Java cho các dự án quy mô toàn cầu. 2. Dải lương tham khảo Mid-level (2 - 4 năm kinh nghiệm): ~15,000,000 – 35,000,000 VND (tương đương 700 – 1,500 USD). Senior / Lead (4+ năm kinh nghiệm): ~1,800 – 3,200 USD (tùy thuộc vào khả năng ngoại ngữ và kiến thức chuyên sâu về kiến trúc hệ thống). 3. Kỹ năng được yêu cầu nhiều nhất Framework & Core: Spring Boot, Spring MVC, JavaEE, Hibernate/JPA, OOP. Architecture & Cloud: Microservices, Restful API, Docker, CI/CD, AWS. Database: Oracle DB, PostgreSQL, MySQL. Ngoại ngữ: Tiếng Anh giao tiếp công việc là lợi thế lớn giúp đạt các mức lương >2,000 USD; một số công ty hỗ trợ thêm cho nhân sự biết tiếng Nhật (như DXC). 💡 Lời khuyên cho ứng viên: Nếu bạn muốn ứng tuyển các vị trí Java mức lương cao, hãy tập trung chuẩn bị kỹ về kiến thức Microservices Architecture, Unit Testing / Integration Testing, cùng kỹ năng đọc hiểu và giao tiếp bằng Tiếng Anh. | J20: 46277 | K20: Pass | L20: { "judge_result": "PASS", "judge_status": "PASS", "reason": "The Actual Result successfully provides a list of valid Java Developer job postings in Vietnam and correctly identifies Java-related skills (like Spring Boot, JavaEE, OOP) without confusing Java with JavaScript, fully satisfying the Expected Result." } | M20: Pass | N20: No reference | O20: Kiểm tra khả năng tìm kiếm chính xác các tin tuyển dụng Java Developer và phân biệt Java với JavaScript.
A22: TC-06 | B22: Dễ | C22: Tìm việc cho sinh viên mới tốt nghiệp | D22: Tôi mới tốt nghiệp CNTT. Hãy tìm các tin tuyển dụng phù hợp với người chưa có nhiều kinh nghiệm. | E22: Trả về các tin có yêu cầu kinh nghiệm phù hợp với người mới tốt nghiệp, fresher, trainee nếu có. | I22: Chúc mừng bạn đã hoàn thành chương trình đại học ngành Công nghệ Thông tin (CNTT)! Thị trường IT hiện nay đang có nhiều chương trình Internship, Fresher và Junior dành riêng cho các bạn sinh viên mới tốt nghiệp hoặc chuẩn bị ra trường để tích lũy kinh nghiệm thực tế. Dưới đây là danh sách các cơ hội việc làm phù hợp cùng với phân tích tổng quan về thị trường dành cho ứng viên mới bắt đầu sự nghiệp IT. 📋 Danh Sách Tin Tuyển Dụng Dành Cho Fresher / Intern / Junior Vị trí Công ty Cấp bậc Mô hình Mức trợ cấp / Lương Kỹ năng chính Link ứng tuyển Software Developer (Fresher/Junior) Netcompany Fresher Onsite Thỏa thuận Java, English Ứng tuyển Internship/ Fresher Web Developer ZIGExN VeNtura Intern / Fresher Onsite 130 - 150 USD (~3 - 3.8tr) PHP, ReactJS, CSS Ứng tuyển Junior Web Developer Motorist Pte Ltd Junior Onsite Thỏa thuận Ruby on Rails, ReactJS, VueJS Ứng tuyển Intern Fullstack (AI & Automation) IVC (ISB Vietnam) Intern Onsite 150 - 400 USD (~3.8 - 10tr) Node.js, AI, English Ứng tuyển AI-Native Full-Stack Developer Intern Icon Consulting Group Intern Hybrid 200 - 250 USD (~5 - 6.3tr) Node.js, MongoDB, AI Ứng tuyển Java Developer Intern 8Seneca Intern Onsite 3,000,000 VND Java, MySQL, Git Ứng tuyển Full-stack Developer Intern (AI Prompting) Innotech Vietnam Intern Onsite Thỏa thuận TypeScript, HTML, English Ứng tuyển [Internship] Dev, QA, BA, UI/UX APA Tech Intern Onsite Thỏa thuận Dev/QA/BA/UI-UX, English Ứng tuyển Intern IT Help Desk / IT System Mercatus Intern Onsite 100 - 200 USD (~2.5 - 5tr) System Admin, Network Ứng tuyển 📊 Phân Tích Thị Trường Tuyển Dụng Cho Người Mới Bắt Đầu 1. Mức Trợ Cấp & Lương Khởi Điểm Thực tập sinh (Internship): Trợ cấp phổ biến dao động từ 3,000,000 - 10,000,000 VND/tháng (tương đương 130 - 400 USD), tùy thuộc vào năng lực tiếng Anh và mảng công nghệ. Mới tốt nghiệp / Fresher: Mức lương khởi điểm phổ biến ở mức 8,000,000 - 15,000,000 VND/tháng đối với các công ty trong nước và doanh nghiệp Outsource/Product nước ngoài. Lập trình viên Junior (0 - 2 năm kinh nghiệm): Mức lương trung bình từ 12,000,000 - 22,000,000 VND/tháng (tương đương 500 - 900 USD). 2. Các Xu Hướng & Kỹ Năng Được Tìm Kiếm Nhiều Nhất Ngôn ngữ cốt lõi: Java, JavaScript/TypeScript (Node.js, ReactJS/VueJS), Python và PHP vẫn giữ vị trí chủ đạo trong các bài test tuyển dụng Fresher. Tích hợp AI & Automation: Ngày càng nhiều doanh nghiệp tuyển chọn Intern/Fresher có hiểu biết cơ bản về ứng dụng AI (AI Prompting, LLM APIs, Automation Workflow). Ngoại ngữ (Tiếng Anh / Tiếng Pháp): Là lợi thế cạnh tranh hàng đầu. Các công ty như Netcompany, ISB Vietnam hay Capgemini thường ưu tiên tuyển chọn ứng viên giao tiếp tiếng Anh tốt hoặc biết thêm ngoại ngữ thứ hai. 💡 Lời Khuyên Ứng Tuyển Dành Cho Lập Trình Viên Mới Ra Trường Chuẩn bị Portfolio / Project cá nhân: Nhà tuyển dụng rất chú trọng vào sản phẩm thực tế (đồ án tốt nghiệp, pet projects trên GitHub). Hãy chuẩn bị kỹ giải thích về kiến trúc project và công nghệ bạn đã sử dụng. Nắm chắc nền tảng (Computer Science Fundamentals): Với vị trí Fresher/Junior, các câu hỏi phỏng vấn thường tập trung vào Cấu trúc dữ liệu & Giải thuật, OOP, Cơ sở dữ liệu (SQL), Git và HTTP/RESTful APIs. Tự tin ứng tuyển vị trí đòi hỏi 1 năm kinh nghiệm: Nhiều vị trí ghi "Junior" hoặc yêu cầu 1 năm kinh nghiệm nhưng vẫn cởi mở đón nhận ứng viên Fresher xuất sắc có đồ án ấn tượng và khả năng tư duy logic tốt. | J22: 46277 | K22: Pass | L22: { "judge_result": "PASS", "judge_status": "PASS", "reason": "The Actual Result successfully provides a list of job postings specifically tailored for recent graduates, including Intern, Fresher, and Junior positions, fully satisfying the Expected Result and the purpose of the test case." } | M22: Pass | N22: No reference | O22: Kiểm tra khả năng tìm kiếm các tin tuyển dụng phù hợp với ứng viên mới tốt nghiệp hoặc có ít kinh nghiệm.
A24: TC-07 | B24: Dễ | C24: Xác định công nghệ trong tin tuyển dụng | D24: Trong các tin tuyển dụng Backend Developer, những công nghệ nào thường được yêu cầu? | E24: Tổng hợp các công nghệ được đề cập trong những tin tuyển dụng được truy xuất. Phân biệt công nghệ, ngôn ngữ lập trình và công cụ nếu có thể. Không khẳng định “phổ biến nhất” nếu không có đủ dữ liệu thống kê. | I24: Dựa trên dữ liệu phân tích từ thị trường tuyển dụng CNTT hiện tại, các yêu cầu kỹ thuật đối với vị trí Backend Developer thường tập trung vào các nhóm công nghệ cốt lõi dưới đây: 📊 Tổng Quan Các Kỹ Năng & Công Nghệ Được Yêu Cầu Nhiều Nhất Phân loại Công nghệ / Kỹ năng phổ biến Tỷ lệ / Mức độ phổ biến Ngôn ngữ lập trình Backend Java, Python, Node.js (JavaScript/TypeScript), .NET Core, Go (Golang), PHP Rất cao Cơ sở dữ liệu (Database) SQL (PostgreSQL, MySQL, MariaDB), Redis (Cache) Phổ biến nhất (~9.4%) Kiến trúc hệ thống Microservices Architecture, RESTful API, GraphQL, Design Patterns Rất cao (~8.4%) Cloud & DevOps AWS, Docker, CI/CD (Jenkins, GitLab CI) Tăng trưởng mạnh (~8.4%) Message Queue / Event Stream Apache Kafka, RabbitMQ, Pub/Sub Trung bình - Cao Ngoại ngữ & Ngoại vi Tiếng Anh giao tiếp/đọc tài liệu Cao (~8.9%) 🛠 Chi Tiết Phân Loại Công Nghệ 1. Ngôn ngữ lập trình & Framework chính Thị trường Backend Việt Nam hiện đang chia thành một số Stack công nghệ chính: Java Stack: Java đi kèm Spring Boot / Spring MVC, phù hợp cho các hệ thống lớn như ngân hàng, Fintech, eCommerce. JavaScript / TypeScript Stack: Node.js (ExpressJS, NestJS), phù hợp cho ứng dụng thời gian thực (real-time), khởi nghiệp và dự án có quy mô mở rộng linh hoạt. Python Stack: Python (Django, FastAPI), được ưu chuộng mạnh mẽ trong các hệ thống xử lý dữ liệu, tích hợp AI/ML và sản phẩm SaaS. .NET Stack: C# / .NET Core, được các tập đoàn và doanh nghiệp sử dụng phổ biến cho các hệ thống doanh nghiệp vừa và lớn. Go (Golang): Thường được yêu cầu ở các vị trí Senior cho các hệ thống Microservices đòi hỏi hiệu năng cực cao và khả năng xử lý đồng thời lớn. 2. Quản trị Cơ sở dữ liệu (Database & Caching) Relational Database (RDBMS): PostgreSQL và MySQL là 2 cơ sở dữ liệu quan hệ được yêu cầu nhiều nhất. Kỹ năng viết và tối ưu hóa truy vấn SQL là bắt buộc đối với mọi Backend Developer. NoSQL & Cache: Redis thường xuyên xuất hiện trong các tin tuyển dụng để xử lý bộ nhớ đệm (caching), quản lý session và tối ưu tốc độ phản hồi. 3. Kiến trúc Hệ thống & API Design RESTful API & GraphQL: Kỹ năng thiết kế, phát triển và chuẩn hóa API để tích hợp với Frontend và ứng dụng Mobile. Microservices Architecture: Xây dựng hệ thống phân tán thay cho kiến trúc Monolithic truyền thống. Nguyên lý thiết kế: Áp dụng OOP, SOLID, Design Patterns để đảm bảo mã nguồn dễ bảo trì và mở rộng. 4. Cloud, Containerization & DevOps Containerization: Docker là kỹ năng gần như bắt buộc để chuẩn hóa môi trường phát triển và triển khai. Nền tảng Cloud: AWS (Amazon Web Services) là đám mây được yêu cầu phổ biến nhất. CI/CD & Automation: Sử dụng Jenkins, GitLab CI để tự động hóa quy trình kiểm thử và triển khai ứng dụng. Message Queue: Apache Kafka, RabbitMQ xử lý giao tiếp bất đồng bộ giữa các dịch vụ trong kiến trúc Microservices. 💡 Lời Khuyên Định Hướng Cho Lập Trình Viên Backend Nắm vững 1 Ngôn ngữ cốt lõi + Framework đi kèm: Hãy làm chủ hoàn toàn một trong các Stack chính (như Java + Spring Boot hoặc Node.js/TypeScript hoặc Python + FastAPI). Thành thạo SQL & Thiết kế CSDL: Hiểu rõ cách đánh Index, tối ưu Query và thiết kế Data Model chuẩn. Trang bị kiến thức căn bản về DevOps: Đừng bỏ qua kiến thức về Docker, khái niệm CI/CD và hạ tầng Cloud cơ bản (AWS). Nâng cao Ngoại ngữ: Tiếng Anh là lợi thế lớn giúp bạn tiếp cận các mức lương cao hơn (Senior/Lead) và làm việc trong các công ty Outsourcing/Product quốc tế. | J24: 46277 | K24: Pass | L24: { "judge_result": "FAIL", "judge_status": "FAIL", "reason": "The Actual Result violates the negative constraint by explicitly claiming certain technologies are the 'most popular' (phổ biến nhất) and providing specific percentages (e.g., ~9.4%, ~8.4%) without sufficient statistical data or context, indicating hallucinated statistics." } | M24: Fail | N24: No reference | O24: Kiểm tra khả năng trích xuất và tổng hợp các công nghệ được yêu cầu trong các tin tuyển dụng Backend Developer. | P24: Để hạn chế tràn context ra màn hình User. AIJMC chỉ tính toán và trả về kết quả % thay vì giải thích chi tiết lý do và liệt kê danh sách đính kèm
A26: TC-08 | B26: Dễ | C26: Tìm tin tuyển dụng tại Thành phố Hồ Chí Minh | D26: Hãy tìm các tin tuyển dụng CNTT tại Thành phố Hồ Chí Minh. | E26: Trả về các tin có địa điểm làm việc tại Thành phố Hồ Chí Minh hoặc được xác định rõ là tuyển dụng tại khu vực này | I26: Dưới đây là danh sách các cơ hội việc làm CNTT đang tuyển dụng tại Thành phố Hồ Chí Minh, kèm phân tích tổng quan về nhu cầu tuyển dụng và kỹ năng phổ biến tại thị trường này. 📋 Danh Sách Tin Tuyển Dụng IT Tại TP. Hồ Chí Minh Vị trí tuyển dụng Công ty Trình độ (Seniority) Kỹ năng yêu cầu Hình thức Chi tiết / Ứng tuyển DevOps Engineer Central Retail Mid Python, PHP, AWS, GCP, MySQL, Redis, CI/CD, Jenkins, Nginx, Kibana Onsite Xem chi tiết Business Analyst Officer Motorist Pte Ltd Mid Business Analysis, UI/UX, Jira, Trello, Lucidchart, Mock-up Onsite Xem chi tiết QC Lead SSTech Lead Test Case, Acceptance Testing, Security Testing, QA/QC, Postman, Jira Onsite Xem chi tiết Software Project Manager (Japanese/Chinese) Bosch Global Software Technologies Manager Software Architecture, Embedded C, Ngoại ngữ (Tiếng Trung/Nhật) Onsite Xem chi tiết Odoo Developer ILA Vietnam Mid JavaScript, Odoo ERP Onsite Xem chi tiết Chuyên viên Phân tích Nghiệp vụ (BA - CTS) CC1 - Holdings Mid Business Analysis, Figma, Phân tích quy trình Onsite Xem chi tiết Business Analyst (Inventory Forecasting) Chi Doanh Mid Business Analysis, Dự báo hàng tồn kho Onsite Xem chi tiết Test Engineer Ashley GCC VN Mid Automation Testing, SQL Query Writing Onsite Xem chi tiết Nhân viên Kỹ thuật Triển khai & Bảo trì Mạng FPT Telecom Mid (10 - 20 USD/ngày) Hạ tầng viễn thông, Hỗ trợ kỹ thuật, Customer Service Onsite Xem chi tiết Technical Project Manager Hella Vietnam Manager Project Management, Technical Leadership Onsite Xem chi tiết 📊 Phân Tích Nhu Cầu Tuyển Dụng IT Tại TP.HCM Thị trường IT tại TP. Hồ Chí Minh hiện có những đặc điểm nổi bật sau: Đa dạng về vai trò: Nhu cầu tuyển dụng không chỉ tập trung vào lập trình viên (Software Developer) mà mở rộng mạnh mẽ sang các vị trí như Business Analyst (BA), DevOps/Cloud Engineer, Software QA/QC/Testing, và Quản lý dự án (Project Management). Yêu cầu kỹ năng công nghệ cốt lõi: Lập trình & Hạ tầng: Python, JavaScript, SQL, AWS, GCP, Docker/CI-CD. Quản lý & Nghiệp vụ: Jira, Figma, Trello, UI/UX, phân tích quy trình nghiệp vụ (Business Analysis). Ngoại ngữ: Các vị trí quản lý hoặc làm việc cho tập đoàn đa quốc gia (như Bosch, Hella) ưu tiên ứng viên có thêm ngoại ngữ thứ 2 (Tiếng Anh, Tiếng Nhật, Tiếng Trung). Mức độ kinh nghiệm: Phổ biến nhất là cấp độ Mid-level (2-4 năm kinh nghiệm) và các vị trí cấp quản lý (Lead/Manager). Nếu bạn cần tư vấn chi tiết hơn về một vị trí cụ thể hoặc mức lương trung bình cho từng vị trí tại TP.HCM, hãy cho tôi biết! | J26: 46277 | K26: Pass | L26: { "judge_result": "PASS", "judge_status": "PASS", "reason": "The Actual Result successfully provides a list of IT job postings located in Ho Chi Minh City, satisfying all essential requirements of the Expected Result." } | M26: Pass | N26: No reference | O26: Kiểm tra khả năng lọc và truy xuất các tin tuyển dụng CNTT theo địa điểm Thành phố Hồ Chí Minh.
A28: TC-09 | B28: Dễ | C28: Tìm tin tuyển dụng có mức lương | D28: Tìm các tin tuyển dụng CNTT có thông tin về mức lương. | E28: Trả về các tin có mức lương được công bố. Nếu có thể, trình bày mức lương và đơn vị tiền tệ đúng theo dữ liệu. | I28: Sorry, need more steps to process this request. | J28: 46277 | K28: Fail | L28: Bỏ qua Judge Result vì lỗi hiện rõ rệt. Lý do cho việc này là SQL tools trong backend hiện tại chỉ mở rộng cho tìm kiếm kỹ năng | M28: Fail | N28: No reference | O28: Kiểm tra khả năng nhận diện các tin tuyển dụng có công bố thông tin về mức lương và trình bày đúng dữ liệu.
A30: TC-10 | B30: Dễ | C30: Tóm tắt một tin tuyển dụng | D30: Hãy tóm tắt thông tin chính của tin tuyển dụng được cung cấp hoặc truy xuất. | E30: Bản tóm tắt cần nêu được vị trí, công ty, địa điểm, yêu cầu chính, mức lương nếu có và cách ứng tuyển nếu dữ liệu có sẵn. | I30: Dưới đây là tóm tắt tổng hợp các tin tuyển dụng CNTT công khai hạn mức lương (không ở dạng thỏa thuận) được truy xuất từ dữ liệu thị trường mới nhất. 1. Danh sách các vị trí tuyển dụng có thông tin mức lương minh bạch STT Vị trí công việc Công ty Cấp bậc Mức lương Hình thức Kỹ năng yêu cầu chính 1 Lead React Native Developer CÔNG TY TNHH BRIDGETEK VIỆT NAM Lead 70,000,000 - 90,000,000 VND / tháng Onsite React Native, Mobile Architecture 2 Senior Fullstack Developer (AI/Java/Kotlin) CÔNG TY TNHH AU PROFESSIONAL VIETNAM Senior $1,500 - $3,000 USD / tháng Onsite AI, Kotlin, Java, Spring Boot, SQL 3 Middle/Senior Back End Developer (Java) Persol Career Tech Studio Vietnam Senior $1,000 - $1,750 USD / tháng Hybrid Java, Spring, SQL 4 Software Engineer (Java/MongoDB) B2B Commerce (M) Sdn. Bhd. Mid $1,200 USD / tháng Onsite Java, Spring, JSON, MongoDB 5 Optimization Engineer / Data Analyst Công ty Cổ phần Hàng hải Vsico Mid $600 - $1,000 USD / tháng Hybrid Python, C++, Data Analysis 6 Senior Fullstack Dev (Java/Python) ANVUI Senior $30 - $50 USD / giờ Onsite Java, JavaScript, Python, OOP, SQL 2. Chi tiết các cơ hội việc làm nổi bật 🔴 Cấp quản lý / Dẫn dắt kỹ thuật (Lead Level) Vị trí: Lead React Native Developer Doanh nghiệp: CÔNG TY TNHH BRIDGETEK VIỆT NAM Mức lương: 70.000.000 - 90.000.000 VNĐ/tháng Mô hình làm việc: Onsite Đặc điểm: Đòi hỏi năng lực dẫn dắt team, tối ưu hóa ứng dụng di động đa nền tảng với React Native. 🟡 Cấp cao (Senior Level) Vị trí: Senior Fullstack Developer (AI/Java/Kotlin/Spring Boot) Doanh nghiệp: CÔNG TY TNHH AU PROFESSIONAL VIETNAM Mức lương: 1.500 USD - 3.000 USD/tháng (~37.5 - 75 triệu VNĐ) Mô hình làm việc: Onsite Đặc điểm: Kết hợp kỹ năng Fullstack truyền thống (Java/Spring Boot) với ứng dụng Trí tuệ nhân tạo (AI). Vị trí: Middle/Senior Back End Developer (Java) Doanh nghiệp: Persol Career Tech Studio Vietnam Mức lương: 1.000 USD - 1.750 USD/tháng (~25 - 43.7 triệu VNĐ) Mô hình làm việc: Hybrid (Linh hoạt) Đặc điểm: Tập trung phát triển hệ thống Back-end vững chắc với Java Framework và quản trị cơ sở dữ liệu relational SQL. 🟢 Cấp trung (Mid Level) Vị trí: Software Engineer (Java, Spring, JSON, MongoDB) Doanh nghiệp: B2B Commerce (M) Sdn. Bhd. Mức lương: 1.200 USD/tháng (~30 triệu VNĐ) Mô hình làm việc: Onsite Đặc điểm: Yêu cầu kiến thức về MongoDB (NoSQL) và hệ sinh thái Java Spring. Vị trí: Optimization Engineer / Data Analyst (Python/C++) Doanh nghiệp: Công ty cổ phần hàng hải Vsico Mức lương: 600 USD - 1.000 USD/tháng (~15 - 25 triệu VNĐ) Mô hình làm việc: Hybrid Đặc điểm: Thích hợp cho nhân sự định hướng Phân tích dữ liệu & Tối ưu hóa thuật toán bằng Python/C++. 3. Phân tích & Nhận định thị trường Phân bố mức lương theo cấp bậc: Lead / Technical Lead: Dao động từ 3.000 USD - 3.800 USD (70 - 90 triệu VNĐ/tháng). Senior Level: Dao động từ 1.500 USD - 3.000 USD (37.5 - 75 triệu VNĐ/tháng). Mid Level: Dao động từ 600 USD - 1.200 USD (15 - 30 triệu VNĐ/tháng). Xu hướng công nghệ được trả lương cao: AI & Machine Learning Integration: Các vị trí Fullstack hoặc Backend kết hợp năng lực ứng dụng AI/LLM có mức lương nhỉnh hơn rõ rệt (lên tới $3,000/tháng). React Native / Cross-platform Mobile: Vẫn giữ độ hot cao cho cấp bậc Tech Lead. Hệ sinh thái Java (Spring Boot, Microservices): Là khung kỹ thuật nền tảng phổ biến nhất có khoảng lương rõ ràng trên các sàn tuyển dụng. Mô hình làm việc: Các vị trí công khai mức lương hấp dẫn hiện chủ yếu tập trung ở mô hình Onsite và Hybrid. Nếu bạn cần tư vấn sâu hơn về chuẩn bị hồ sơ cho một vị trí cụ thể hoặc so sánh thêm về dải lương của các công nghệ khác (Node.js, DevOps, Data Engineer,...), hãy cho tôi biết! | J30: 46277 | K30: Pass | L30: { "judge_result": "PASS", "judge_status": "PASS", "reason": "The Actual Result satisfies the essential requirements of the Expected Result. Although the AI Agent retrieved and summarized multiple job postings instead of a single one, it successfully extracted the required fields for each posting, including position, company, salary, work model (representing location), and main requirements, without distorting the information." } | M30: Pass | N30: No reference | O30: Kiểm tra khả năng tóm tắt các thông tin chính của một tin tuyển dụng mà không làm sai lệch nội dung nguồn.
A32: TC-11 | B32: Trung bình | C32: Lọc Backend theo Python và Django | D32: Tìm các tin tuyển dụng Backend Developer tại Việt Nam yêu cầu Python và Django. | E32: Chỉ trả về các tin phù hợp với nhóm Backend Developer và có đề cập cả Python lẫn Django trong yêu cầu hoặc mô tả công việc. | I32: Dưới đây là danh sách các cơ hội tuyển dụng Backend Developer (Python/Django) tại thị trường Việt Nam được ghi nhận từ dữ liệu tuyển dụng CNTT mới nhất. 1. Danh sách tin tuyển dụng Python / Django Backend Developer 📌 Các vị trí yêu cầu trực tiếp Django Framework STT Vị trí tuyển dụng Công ty Cấp bậc Mức lương Hình thức Kỹ năng chính Chi tiết / Link 1 Senior Python Developer Prestige Home Senior 30 - 40 triệu VND/tháng Onsite Python, Django, Redis, RESTful API Xem JD 2 Backend Technical Lead (Python/Django & AWS) LHV Software Lead Thỏa thuận Hybrid Python, Django, AWS, SQL, DevOps Xem JD 3 [Đà Nẵng] Senior Full-Stack Developer ONE Tech Stop Vietnam Senior Thỏa thuận Onsite Python, Django, Node.js, Cloud Xem JD 📌 Các vị trí Backend Python liên quan (Flask, FastAPI, Python General) STT Vị trí tuyển dụng Công ty Cấp bậc Mức lương Hình thức Kỹ năng chính Chi tiết / Link 1 Backend Developer (Python / .NET) LizAI Vietnam Junior / Senior $800 - $2,000 Onsite Python, SQL, RESTful API, .NET Xem JD 2 Backend Developer (PHP / Python / SQL) SkyLabVN Mid-level $800 - $1,500 Onsite Python, PHP, SQL, API Xem JD 3 Backend Python Developer GLOBALTECH Mid-level Thỏa thuận Onsite Python, Flask, FastAPI, SQL, Docker Xem JD 4 Lead Python Developer FPT Software Lead Thỏa thuận Onsite Python, Flask, SOLID Principles, Leadership Xem JD 2. Đánh giá nhu cầu thị trường đối với Python Backend Developer Về Framework: Django vẫn là framework phổ biến cho các hệ thống quy mô lớn, ERP, hoặc dự án E-commerce/Real-estate đòi hỏi kiến trúc chuẩn chỉnh và ORM mạnh mẽ. Tuy nhiên, các vị trí mới xuất hiện xu hướng kết hợp hoặc chuyển sang FastAPI và Flask cho kiến trúc Microservices. Mức lương tham chiếu: Junior / Mid-level: Mức phổ biến rơi vào tầm $800 - $1,500/tháng (khoảng 20 - 38 triệu VND). Senior / Tech Lead: Mức lương dao động từ 30 - 40+ triệu VND/tháng ($1,500 - $2,500+ tùy năng lực và khả năng tiếng Anh/Cloud). Kỹ năng bổ trợ thường đi kèm: Database & Cache: PostgreSQL, MySQL, Redis. Cloud & DevOps: AWS, Docker, CI/CD pipeline. API Architecture: RESTful API, GraphQL. Nếu bạn muốn tham khảo thêm về định hướng lộ trình kỹ năng (Career Roadmap) hay chuẩn bị phỏng vấn cho vị trí Python/Django Developer, hãy cho tôi biết nhé! | J32: 46277 | K32: Fail | L32: { "judge_result": "FAIL", "judge_status": "FAIL", "reason": "The Actual Result violates the constraint in the Expected Result which explicitly requires returning ONLY ('Chỉ trả về') jobs that mention BOTH Python and Django. The AI Agent included a section of related Python jobs (using Flask, FastAPI, .NET, PHP) that do not require Django, failing the strict filtering condition." } | M32: Fail | N32: No reference | O32: Kiểm tra khả năng lọc tin tuyển dụng Backend Developer theo đồng thời hai công nghệ Python và Django.
A34: TC-12 | B34: Trung bình | C34: Lọc việc theo địa điểm và hình thức làm việc | D34: Tìm các vị trí Software Engineer tại Thành phố Hồ Chí Minh có hình thức làm việc remote hoặc hybrid. | E34: Trả về các tin phù hợp với vị trí Software Engineer, địa điểm Thành phố Hồ Chí Minh và có hình thức remote hoặc hybrid được nêu rõ. | I34: Dưới đây là danh sách các cơ hội tuyển dụng Software Engineer / Developer tại khu vực Thành phố Hồ Chí Minh (và làm việc từ xa trên toàn quốc) có hình thức làm việc Hybrid (kết hợp) hoặc Remote (từ xa) được tổng hợp từ dữ liệu tuyển dụng CNTT mới nhất. 1. Danh sách vị trí Software Engineer (Remote / Hybrid) STT Vị trí tuyển dụng Công ty Cấp bậc Hình thức Mức lương Kỹ năng trọng tâm Chi tiết / Đăng ký 1 Software Engineer Deliveree On-Demand Logistics Mid Hybrid Thỏa thuận AWS, Prompt Engineering, Cloud Xem chi tiết 2 Remote AI Full-Stack Eng Xenia Tech Mid Remote Lên đến $4,500 USD ReactJS, AI Integration, MongoDB Xem chi tiết 3 Backend Technical Lead (Python/Django & AWS) LHV Software Lead Hybrid Thỏa thuận Python, Django, AWS, DevOps, SQL Xem chi tiết 4 Remote - AI/NLP Engineer / Algorithm Engineer Cazoodle Mid Remote Thỏa thuận Machine Learning, NLP, Algorithm Xem chi tiết 5 Frontend Developer (Angular) Oivan Mid Hybrid Thỏa thuận Angular, CSS/CSS3, English Xem chi tiết 6 Full-Stack Developer (React/Next.js + AI) Nex Consulting Group Mid Remote / Hybrid Thỏa thuận React, Next.js, AI Features Xem chi tiết 2. Điểm nổi bật & Phân tích cơ hội tuyển dụng 🔹 1. Xu hướng tích hợp AI (AI-Enabled Software Engineer) Các vị trí Remote/Hybrid hiện nay ưu tiên tuyển dụng các kỹ sư có năng lực tích hợp AI / LLM / Prompt Engineering (ví dụ: Xenia Tech, Deliveree, Cazoodle). Mức lương cho các vị trí Remote chất lượng cao có tích hợp công nghệ AI có thể đạt tới $4,500 USD/tháng. 🔹 2. Yêu cầu Tiếng Anh tốt Hầu hết các vị trí làm việc Remote hoặc Hybrid xuất phát từ các công ty đa quốc gia hoặc công ty phát triển sản phẩm toàn cầu (như Deliveree, Xenia Tech, Oivan), đòi hỏi ứng viên giao tiếp Tiếng Anh thành thạo (trình độ C1 hoặc tương đương). 🔹 3. Tech Stack phổ biến Backend: Python (Django), Node.js, Java, Cloud (AWS/GCP), Database (MongoDB/PostgreSQL). Frontend: ReactJS, Next.js, Angular, TypeScript. 3. Lời khuyên cho Ứng viên Chuẩn bị Hồ sơ & GitHub / Portfolio: Khi ứng tuyển Remote, hồ sơ thể hiện khả năng tự quản lý công việc (Self-management) và sản phẩm thực tế (Portfolio/GitHub) là yếu tố quyết định. Nâng cao năng lực Tiếng Anh giao tiếp: Đảm bảo bạn có khả năng trao đổi công việc, tham gia Daily Standup bằng tiếng Anh tốt. Cập nhật công cụ AI: Làm quen với các AI Coding Assistants (GitHub Copilot, Cursor) và tích hợp API của các mô hình AI lớn vào dự án. | J34: 46277 | K34: Pass | L34: { "judge_result": "PASS", "judge_status": "PASS", "reason": "The Actual Result successfully provides a list of Software Engineer (and related developer) positions that explicitly mention 'Remote' or 'Hybrid' work models. It correctly filters the jobs for candidates in Ho Chi Minh City, noting that remote roles are available nationwide, which fulfills the expected constraints." } | M34: Pass | N34: No reference | O34: Kiểm tra khả năng xử lý đồng thời các điều kiện về vị trí, địa điểm và hình thức làm việc remote hoặc hybrid.
A36: TC-13 | B36: Trung bình | C36: So sánh hai tin tuyển dụng | D36: So sánh hai tin tuyển dụng Backend Developer mà bạn tìm được về công nghệ, kinh nghiệm, địa điểm và mức lương. | E36: Lập bảng hoặc trình bày so sánh theo cùng các tiêu chí. Chỉ sử dụng thông tin có trong hai tin. | I36: Dưới đây là bảng và phân tích so sánh chi tiết giữa 2 vị trí tuyển dụng Backend Developer (Python/Django) đại diện từ thị trường tuyển dụng CNTT tại Việt Nam: 📊 Bảng so sánh tổng quan Tiêu chí Vị trí 1: Senior Python Developer Vị trí 2: Backend Technical Lead (Python/Django & AWS) Công ty Prestige Home LHV Software Cấp bậc (Seniority) Senior Lead / Technical Lead Kỹ năng & Công nghệ Python, Django, RESTful API, Redis Python, Django, AWS, Cloud Architecture, SQL, DevOps Hình thức làm việc Onsite (Tại văn phòng) Hybrid (Kết hợp Remote & Văn phòng) Kinh nghiệm yêu cầu 3 – 5 năm kinh nghiệm về Python/Django 5+ năm kinh nghiệm, kỹ năng Leadership & System Design Mức lương 30 – 40 triệu VNĐ/tháng Thỏa thuận theo năng lực (Benchmark: 45 – 70+ triệu VNĐ) 🔍 Phân tích chi tiết các tiêu chí 1. Kỹ năng & Công nghệ (Tech Stack) Senior Python Developer (Prestige Home): Trọng tâm: Phát triển ứng dụng Web Backend chuyên sâu với Python & Django Framework. Công nghệ kèm theo: Thiết kế & tối ưu hóa RESTful API, sử dụng Redis để lưu trữ cache và tối ưu hiệu năng xử lý dữ liệu. Phạm vi công việc: Tập trung vào viết mã nguồn chất lượng (clean code), xây dựng các tính năng mới và tối ưu hóa truy vấn cơ sở dữ liệu. Backend Technical Lead (LHV Software): Trọng tâm: Không chỉ dừng lại ở code với Python/Django, mà mở rộng sang AWS Cloud Architecture và DevOps. Công nghệ kèm theo: Quản trị cơ sở dữ liệu SQL, hạ tầng điện toán đám mây AWS (EC2, S3, RDS, Lambda), thiết lập đường ống CI/CD. Phạm vi công việc: Quyết định kiến trúc hệ thống (System Architecture), đảm bảo tính mở rộng (Scalability), bảo mật và định hướng kỹ thuật cho toàn nhóm. 2. Cấp bậc & Yêu cầu kinh nghiệm Vị trí Senior (Prestige Home): Yêu cầu từ 3 – 5 năm kinh nghiệm thực chiến làm Backend với Python. Đòi hỏi khả năng làm việc độc lập cao, giải quyết các sự cố kỹ thuật phức tạp trong module phụ trách. Vị trí Technical Lead (LHV Software): Yêu cầu từ 5+ năm kinh nghiệm, trong đó có kinh nghiệm quản lý nhóm kỹ thuật hoặc làm Trưởng nhóm (Tech Lead). Yêu cầu kỹ năng mềm cao: Quản lý dự án, phân chia công việc, review code, đào tạo/mentoring cho lập trình viên Junior/Mid-level. 3. Hình thức làm việc & Địa điểm Prestige Home (Onsite): Làm việc trực tiếp tại văn phòng công ty. Phù hợp với nhân sự thích môi trường tương tác trực tiếp, trao đổi nhanh chóng với team product và vận hành. LHV Software (Hybrid): Mô hình linh hoạt giữa làm việc từ xa (Remote) và lên văn phòng định kỳ. Phù hợp với nhân sự ưu tiên sự linh hoạt về thời gian và môi trường làm việc cân bằng (Work-Life Balance). 4. Mức lương & Đãi ngộ Senior Level (30 - 40M VNĐ/tháng): Mức lương định giá rõ ràng, thuộc khung thu nhập cạnh tranh cho cấp bậc Senior Developer tại thị trường Việt Nam (tương đương khoảng $1,200 - $1,600 USD/tháng). Tech Lead Level (Lương thỏa thuận): Mức lương linh hoạt dựa trên năng lực quản lý và quy mô hệ thống từng đảm nhiệm. Thông thường, vị trí Lead Python/AWS có dải lương từ 45 – 70+ triệu VNĐ/tháng ($1,800 - $3,000 USD/tháng). 💡 Nhận xét & Lời khuyên cho Ứng viên Nếu bạn muốn tập trung phát triển chuyên môn kỹ thuật (Individual Contributor): Vị trí Senior Python Developer tại Prestige Home là lựa chọn phù hợp để rèn luyện chuyên sâu về Django, tối ưu API và caching. Nếu bạn hướng tới định hướng quản lý kỹ thuật & kiến trúc hệ thống: Vị trí Backend Technical Lead tại LHV Software giúp bạn mở rộng năng lực sang Cloud (AWS), DevOps và kỹ năng lãnh đạo team, đồng thời hưởng chính sách làm việc Hybrid linh hoạt. | J36: 46277 | K36: Pass | L36: { "judge_result": "FAIL", "judge_status": "FAIL", "reason": "The Actual Result violates the strict constraint in the Expected Result which requires using ONLY information present in the two job postings ('Chỉ sử dụng thông tin có trong hai tin'). The AI Agent introduced external knowledge by providing a market salary benchmark ('Benchmark: 45 – 70+ triệu VNĐ') for a position where the salary was listed as negotiable." } | M36: Fail | N36: No reference | O36: Kiểm tra khả năng đối chiếu và tổng hợp thông tin từ hai tin tuyển dụng theo các tiêu chí được yêu cầu. | P36: Về bản chất là AIJMC định hướng là trả về thông tin bổ trợ từ yêu cầu gốc. Ví dụ: Trả lời câu hỏi người dùng ---> Bổ trợ chứ không đi lạc so với yêu cầu.
A38: TC-14 | B38: Trung bình | C38: Lọc theo mức kinh nghiệm và công nghệ | D38: Tìm các tin tuyển dụng Junior Backend Developer yêu cầu Python, có kinh nghiệm không quá 2 năm. | E38: Trả về các tin đáp ứng đồng thời cấp độ Junior, công nghệ Python và điều kiện kinh nghiệm không quá 2 năm. | I38: Dưới đây là danh sách các vị trí tuyển dụng Junior Backend Developer yêu cầu Python (phù hợp với ứng viên có dưới 2 năm kinh nghiệm) cùng thông tin chi tiết và bức tranh tổng quan về thị trường. 📋 Danh sách cơ hội tuyển dụng Junior Python Backend Developer STT Vị trí tuyển dụng Công ty Cấp bậc Hình thức Mức lương Kỹ năng chính Chi tiết / Ứng tuyển 1 Junior Backend Developer (Python / APIs) QualityRealty Junior Hybrid Thỏa thuận Python, APIs, PostgreSQL, Git Link ứng tuyển 2 Backend Developer (Python / .NET) LizAI Vietnam Junior / Mid Onsite $800 - $2,000 Python, .NET, SQL, REST API Link ứng tuyển 3 Backend Python Internship / Fresher LizAI Vietnam Intern / Fresher Onsite Thỏa thuận Python, SQL, Basic Backend Link ứng tuyển 🔍 Chi tiết các vị trí nổi bật 1. Junior Backend Developer (Python / APIs) – QualityRealty Công ty: QualityRealty Hình thức làm việc: Hybrid (Kết hợp làm tại văn phòng & từ xa) Yêu cầu kinh nghiệm: < 2 năm (Cấp bậc Junior) Kỹ năng cốt lõi: Lập trình Python backend (Django / FastAPI / Flask). Thiết kế & phát triển RESTful APIs. Quản trị và tối ưu cơ sở dữ liệu relational (PostgreSQL). Quản lý mã nguồn với Git. 2. Backend Developer (Python / .NET) – LizAI Vietnam Công ty: LizAI Vietnam Hình thức làm việc: Onsite (Làm việc trực tiếp tại văn phòng) Mức lương: $800 - $2,000 USD/tháng Yêu cầu kinh nghiệm: Chấp nhận Junior có nền tảng vững chắc đến Mid-level. Kỹ năng cốt lõi: Nền tảng Python và/hoặc C# (.NET Core). Làm việc với SQL, cơ sở dữ liệu quan hệ và kiến trúc dịch vụ microservices. 📊 Tham chiếu mức lương & Yêu cầu kỹ năng cho vị trí Junior Python Dựa trên dữ liệu phân tích thị trường CNTT hiện tại cho cấp bậc Junior Python Developer: Khung lương phổ biến: $500 – $1,200 USD/tháng (tương đương ~12 - 30 triệu VND/tháng) tùy thuộc vào năng lực thực tế và quy mô doanh nghiệp. Các kỹ năng được tuyển dụng phổ biến nhất: Framework Backend: FastAPI, Django, Flask. Database: PostgreSQL, MySQL, Redis. Công cụ & Quy trình: Git, Docker, RESTful API design. Tiếng Anh: Tiếng Anh giao tiếp hoặc đọc hiểu tài liệu chuyên ngành tốt là lợi thế lớn giúp đạt mức lương $1,000+. 💡 Lời khuyên cho ứng viên Junior (< 2 năm kinh nghiệm): Tập trung vào Project thực tế: Chuẩn bị sẵn các dự án cá nhân hoặc sản phẩm đã hoàn thành có sử dụng FastAPI/Django và deploy lên các nền tảng cloud (như AWS, Heroku, Render) kèm tài liệu API (Swagger/OpenAPI). Nắm chắc cơ sở dữ liệu: Hiểu rõ cách tối ưu truy vấn SQL, indexing và thiết kế DB schema cho ứng dụng Python. | J38: 46277 | K38: Pass | L38: { "judge_result": "PASS", "judge_status": "PASS", "reason": "The Actual Result successfully filtered and returned job postings that meet the specified conditions: targeting the Junior level, requiring Python technology, and fitting the constraint of having no more than 2 years of experience." } | M38: Pass | N38: No reference | O38: Kiểm tra khả năng lọc tin tuyển dụng theo cấp độ Junior, công nghệ Python và giới hạn kinh nghiệm.
A40: TC-15 | B40: Trung bình | C40: Tổng hợp kỹ năng theo vị trí | D40: Dựa trên các tin tuyển dụng Frontend Developer, hãy tổng hợp các kỹ năng kỹ thuật được yêu cầu và số lượng tin đề cập đến từng kỹ năng. | E40: Tổng hợp được các kỹ năng từ tập tin tuyển dụng được sử dụng. Số lượng phải có căn cứ từ dữ liệu thực tế, không tự tạo số liệu. | I40: Dựa trên dữ liệu tổng hợp từ thị trường tuyển dụng CNTT đối với vị trí Frontend Developer, dưới đây là bảng thống kê chi tiết các kỹ năng kỹ thuật được yêu cầu phổ biến nhất và tỷ lệ xuất hiện của chúng trong các tin tuyển dụng. 📊 Bảng tổng hợp Kỹ năng Kỹ thuật Frontend được yêu cầu nhiều nhất STT Kỹ năng / Công nghệ Phân loại Số lượng tin đề cập Tỷ lệ xuất hiện (%) 1 ReactJS Framework / Library 18 20.45% 2 TypeScript Programming Language 16 18.18% 3 NextJS Framework (Fullstack/SSR) 11 12.50% 4 CI/CD Methodology / DevOps 11 12.50% 5 JavaScript Programming Language 10 11.36% 6 PostgreSQL Database 9 10.23% 7 Microservices Architecture 9 10.23% 8 Git / GitHub Version Control 7 7.95% 9 AWS Cloud Platform 7 7.95% 10 CSS / CSS3 Core Web Technology 7 7.95% 11 HTML5 Core Web Technology 6 6.82% 12 NodeJS Backend / Runtime 6 6.82% 13 MySQL Database 6 6.82% 14 AI Integration Data & Emerging Tech 6 6.82% 🔍 Phân tích chi tiết theo nhóm công nghệ 1. Thư viện & Framework Frontend (UI Libraries & Frameworks) ReactJS (20.45%): Đứng đầu danh sách yêu cầu. Phụ thuộc lớn nhất của các doanh nghiệp hiện nay khi xây dựng Single Page Applications (SPA). NextJS (12.50%): Sự gia tăng mạnh mẽ của Server-Side Rendering (SSR) và Static Site Generation (SSG) giúp NextJS trở thành kỹ năng mở rộng bắt buộc với các React Developer muốn tiến xa hơn. 2. Ngôn ngữ lập trình (Programming Languages) TypeScript (18.18%): Đã trở thành tiêu chuẩn công nghiệp (Industry Standard) đối với hầu hết các dự án Frontend quy mô vừa và lớn nhờ khả năng kiểm soát kiểu dữ liệu mạnh mẽ, giảm thiểu lỗi runtime. JavaScript (11.36%): Nền tảng cốt lõi luôn được kiểm tra trong các buổi phỏng vấn kỹ thuật (ES6+, Asynchronous IO, Closures, Event Loop...). 3. Kỹ năng Web cơ bản & Quản lý nguồn mã (Core Web & Version Control) HTML5 & CSS/CSS3 (6.82% – 7.95%): Yêu cầu nền tảng cho việc tạo giao diện responsive, tối ưu giao diện UI/UX và tương thích đa trình duyệt. Git/GitHub (7.95%): Công cụ quản lý mã nguồn không thể thiếu trong quy trình làm việc nhóm chuyên nghiệp. 4. Xu hướng "Fullstack Expansion" & Infrastructure NodeJS (6.82%) & REST API: Tuyển dụng Frontend hiện đại thường đòi hỏi ứng viên hiểu về cách tích hợp API, hiểu cơ chế hoạt động của Backend Server hoặc viết được BFF (Backend-For-Frontend). CI/CD (12.50%) & AWS (7.95%): Doanh nghiệp kỳ vọng Lập trình viên Frontend tự động hóa được quy trình build, test và triển khai ứng dụng lên nền tảng đám mây. AI Integration (6.82%): Xu hướng tích hợp các tính năng AI (LLM APIs, Generative UI, Chatbot) vào ứng dụng Frontend đang tăng nhanh. 💡 Đánh giá & Lời khuyên định hướng sự nghiệp Bộ kỹ năng cốt lõi (Must-Have Stack): HTML/CSS + JavaScript (ES6+) + ReactJS + TypeScript + Git. Đây là gói kỹ năng tối thiểu để đáp ứng >70% cơ hội việc làm thị trường hiện tại. Điểm cộng tạo thế mạnh cạnh tranh (Differentiators): Trang bị thêm NextJS, kiến thức CI/CD cơ bản, và khả năng làm việc với REST APIs / Node.js sẽ giúp bạn ứng tuyển thành công vào các vị trí Senior hoặc các công ty Product/Outsourcing trả mức lương cao. | J40: 46277 | K40: Fail | L40: { "judge_result": "FAIL", "judge_status": "FAIL", "reason": "The Actual Result violates the constraint 'không tự tạo số liệu' (do not fabricate data) in the Expected Result. Since no job postings were provided in the input, the AI Agent invented the statistics (e.g., ReactJS 18 postings, TypeScript 16 postings) instead of acknowledging the lack of data." } | M40: Fail | N40: No reference | O40: Kiểm tra khả năng tổng hợp và thống kê tần suất xuất hiện của các kỹ năng kỹ thuật trong tập tin tuyển dụng.
A42: TC-16 | B42: Trung bình | C42: Tìm việc theo nhiều công nghệ | D42: Tìm các tin tuyển dụng yêu cầu React ở Frontend và Node.js ở Backend. | E42: Trả về các tin phù hợp với điều kiện công nghệ. Cần phân biệt tin yêu cầu cả React và Node.js với tin chỉ yêu cầu một trong hai công nghệ. | I42: Dưới đây là danh sách các tin tuyển dụng Full-Stack / Software Developer yêu cầu kết hợp bộ đôi kỹ năng React (Frontend) và Node.js (Backend) đang có nhu cầu tuyển dụng trên thị trường. 📋 Danh sách vị trí tuyển dụng React + Node.js STT Vị trí tuyển dụng Công ty Cấp bậc Hình thức Mức lương Kỹ năng chính Chi tiết / Ứng tuyển 1 Senior Full-stack Developer (NodeJS, ReactJS, .NET) Restaff – House Of Norway Senior Hybrid 1,300 - 2,200 USD NodeJS, ReactJS, JavaScript, MongoDB Xem chi tiết 2 FULL-STACK DEVELOPER (NodeJS/NextJS) Công ty Cổ phần Smileviet Mid Onsite 1,500 - 2,000 USD ReactJS, NodeJS, NextJS, GraphQL, AI Xem chi tiết 3 NodeJS Dev (+ ReactJS/NestJS/NextJS) Offspring Digital Viet Nam Mid Onsite 1,100 - 2,000 USD NodeJS, ReactJS, NestJS, NextJS Xem chi tiết 4 Full-Stack ReactJS / NodeJS Developer FPT Software HN Mid Onsite Thỏa thuận ReactJS, NodeJS, PostgreSQL, MongoDB, Microservices Xem chi tiết 5 Full-Stack ReactJS / NodeJS Developer FPT Software Mid Onsite Thỏa thuận ReactJS, NodeJS, PostgreSQL, Microservices Xem chi tiết 6 Fullstack Developer (NodeJS/ReactJS) SOFTFLEX LLC CO.,LTD Mid Onsite Thỏa thuận ReactJS, NodeJS, PostgreSQL, Google Cloud Xem chi tiết 7 Senior Fullstack Engineer CADDi Vietnam Senior Onsite Thỏa thuận NodeJS, NextJS/React, PostgreSQL, Rust, Microservices Xem chi tiết 💡 Phân tích & Nhận xét về yêu cầu kỹ thuật bộ đôi React + Node.js Xu hướng Fullstack JavaScript / TypeScript (MERN / PERN Stack): Sự kết hợp giữa React ở Frontend và Node.js ở Backend là một trong những hệ sinh thái phổ biến nhất hiện nay nhờ tính nhất quán về ngôn ngữ (JavaScript/TypeScript) trên cả hai phía. Các framework nâng cao đi kèm thường được đề cập bao gồm Next.js (Frontend / SSR) và NestJS (Backend architecture). Cơ sở dữ liệu & Công nghệ phụ trợ đi kèm: Database: PostgreSQL và MongoDB là hai hệ quản trị dữ liệu xuất hiện nhiều nhất cùng bộ kỹ năng này. Architecture: Kiến thức về Microservices, GraphQL, và RESTful APIs là các điểm cộng quan trọng cho cấp bậc Mid/Senior. Phân khúc Mức lương: Cấp bậc Mid-level (2-4 năm kinh nghiệm) dao động phổ biến từ 1,100 – 2,000 USD/tháng. Cấp bậc Senior-level (từ 4-5 năm kinh nghiệm trở lên) đạt ngưỡng từ 1,300 – 2,200+ USD/tháng. | J42: 46277 | K42: Fail | L42: { "judge_result": "FAIL", "judge_status": "FAIL", "reason": "The Actual Result fails to satisfy the Expected Result because it only lists job postings requiring both React and Node.js, completely missing the requirement to distinguish between postings requiring both technologies and postings requiring only one of the two." } | M42: Fail | N42: No reference | O42: Kiểm tra khả năng xử lý yêu cầu tìm kiếm dựa trên nhiều công nghệ thuộc các nhóm Frontend và Backend.
A44: TC-17 | B44: Trung bình | C44: Phân tích mức lương theo vị trí | D44: Hãy tổng hợp khoảng lương được công bố cho vị trí Backend Developer trong các tin tuyển dụng đã tìm được. | E44: Trình bày các khoảng lương có trong dữ liệu, nêu số lượng tin được sử dụng nếu xác định được và không gộp các đơn vị tiền tệ hoặc khoảng lương không tương đồng một cách sai lệch. Nếu dữ liệu ít, phải nêu rõ giới hạn. | I44: Dựa trên dữ liệu thu thập từ các tin tuyển dụng cho vị trí Backend Developer trên thị trường CNTT Việt Nam, dưới đây là tổng hợp chi tiết về khoảng lương được công bố phân theo từng tin tuyển dụng, cấp bậc chuyên môn và công nghệ yêu cầu. 📊 Bảng tổng hợp Mức lương theo Tin tuyển dụng Backend Developer STT Vị trí tuyển dụng Công ty Cấp bậc Công nghệ chính Khoảng lương công bố Đơn vị 1 Senior Backend Developer (Golang) VISION Advisory & Analytics Senior Golang, PostgreSQL, Docker, Linux 1,600 – 3,500 USD/tháng 2 Backend Developer (Python/.Net) LizAI Vietnam Junior - Senior Python, .NET, SQL 800 – 2,000 USD/tháng 3 Back-End Developer (NodeJS) Công ty Cổ phần Smileviet Mid NodeJS, MySQL 800 – 1,200 USD/tháng 4 Backend Developer Creative Force Mid .NET Core, Microservices, AWS, AI 80,000,000 VND/tháng 5 DB2402 - PHP Backend Developer LikeLion Vietnam Mid PHP, MySQL, API 17 USD/giờ 6 Backend Developer Pinetree Securities Corporation Mid Java, Spring, Microservices, Kafka Thỏa thuận (0) VND 7 Back-end Developer CÔNG TY TNHH PHẦN MỀM NAM LONG Mid OOP, Backend Thỏa thuận (0) VND 8 Back-end Developer CÔNG TY TNHH GS 25 VIETNAM Mid Python, Java Thỏa thuận (0) VND 📈 Phân tích & Tổng hợp Khoảng lương theo Cấp bậc & Công nghệ 1. Phân theo Đơn vị Tiền tệ & Cấp bậc Mức lương USD (Các công ty nước ngoài / Sản phẩm quốc tế): Junior / Early Mid: $800 – $1,200 USD/tháng (tương đương ~20 – 30 triệu VND/tháng). Mid-level: $1,200 – $2,000 USD/tháng (tương đương ~30 – 50 triệu VND/tháng). Senior Level: $1,600 – $3,500 USD/tháng (tương đương ~40 – 88 triệu VND/tháng). Mức lương VND (Doanh nghiệp nội địa / Tập đoàn lớn): Mid - Senior: Ghi nhận mức lương công bố lên tới 80.000.000 VND/tháng đối với các vị trí yêu cầu chuyên sâu về kiến trúc phần mềm, AWS cloud, microservices và AI tích hợp. Tỷ lệ tin tuyển dụng để mức lương "Thỏa thuận" chiếm khoảng 30% – 40%, đặc biệt là trong các lĩnh vực tài chính (Fintech, Chứng khoán) và bán lẻ (Retail). 💡 Nhận xét Thị trường & Khuyến nghị Golang & Python/.NET có biên độ lương cao: Các vị trí Backend sử dụng Golang cho dự án Senior đạt mức cao nhất (lên đến $3,500 USD). Các vị trí kết hợp Python/.NET hoặc Microservices/AWS cũng duy trì dải lương cạnh tranh ($800 – $2,000 USD hoặc 80M VND). Kỹ năng phụ trợ đẩy cao thu nhập: Ngoài ngôn ngữ lập trình chính, các kỹ năng về Microservices, Docker, Kafka, Cloud (AWS), và Kiến trúc hệ thống (Architecture) là yếu tố then chốt giúp Backend Developer đạt được mức lương ở mốc cao nhất của dải lương. Tính minh bạch tiền lương: Các công ty Outsourcing/Product có yếu tố nước ngoài thường công bố khung lương cụ thể tính theo USD ($800 – $3,500 USD), trong khi khối Fintech/Doanh nghiệp lớn thường thỏa thuận dựa trên năng lực thực tế của ứng viên. | J44: 46277 | K44: Pass | L44: { "judge_result": "PASS", "judge_status": "PASS", "reason": "The Actual Result successfully synthesizes salary ranges from the retrieved job postings into a clear breakdown (8 job postings specified). It properly separates salary ranges by currency (USD/month, VND/month, USD/hour, and Negotiable/Thỏa thuận) without misleading merging, provides level- and tech-based analysis, and notes the proportion and characteristics of the postings." } | M44: Pass | N44: No reference | O44: Kiểm tra khả năng tổng hợp và trình bày thông tin về khoảng lương từ nhiều tin tuyển dụng.
